<?xml version="1.0" ?>
<!-- =================================================================================== -->
<!-- |    This document was autogenerated by xacro from /home/takane/catkin_ws/src/moveit_sample_description/urdf/moveit_sample.xacro | -->
<!-- |    EDITING THIS FILE BY HAND IS NOT RECOMMENDED                                 | -->
<!-- =================================================================================== -->
<robot name="moveit_sample">
    <material name="silver_default">
        <color rgba="0.700 0.700 0.700 1.000" />
    </material>
    <material name="_">
        <color rgba="0.6274509803921569 0.6274509803921569 0.6274509803921569 1.0" />
    </material>
    <transmission name="rev1_tran">
        <type>transmission_interface/SimpleTransmission</type>
        <joint name="rev1">
            <hardwareInterface>hardware_interface/EffortJointInterface</hardwareInterface>
        </joint>
        <actuator name="rev1_actr">
            <hardwareInterface>hardware_interface/EffortJointInterface</hardwareInterface>
            <mechanicalReduction>1</mechanicalReduction>
        </actuator>
    </transmission>
    <transmission name="rev2_tran">
        <type>transmission_interface/SimpleTransmission</type>
        <joint name="rev2">
            <hardwareInterface>hardware_interface/EffortJointInterface</hardwareInterface>
        </joint>
        <actuator name="rev2_actr">
            <hardwareInterface>hardware_interface/EffortJointInterface</hardwareInterface>
            <mechanicalReduction>1</mechanicalReduction>
        </actuator>
    </transmission>
    <transmission name="rev3_tran">
        <type>transmission_interface/SimpleTransmission</type>
        <joint name="rev3">
            <hardwareInterface>hardware_interface/EffortJointInterface</hardwareInterface>
        </joint>
        <actuator name="rev3_actr">
            <hardwareInterface>hardware_interface/EffortJointInterface</hardwareInterface>
            <mechanicalReduction>1</mechanicalReduction>
        </actuator>
    </transmission>
    <transmission name="d_rev1_tran">
        <type>transmission_interface/SimpleTransmission</type>
        <joint name="d_rev1">
            <hardwareInterface>hardware_interface/EffortJointInterface</hardwareInterface>
        </joint>
        <actuator name="d_rev1_actr">
            <hardwareInterface>hardware_interface/EffortJointInterface</hardwareInterface>
            <mechanicalReduction>1</mechanicalReduction>
        </actuator>
    </transmission>
    <transmission name="d_rev2_tran">
        <type>transmission_interface/SimpleTransmission</type>
        <joint name="d_rev2">
            <hardwareInterface>hardware_interface/EffortJointInterface</hardwareInterface>
        </joint>
        <actuator name="d_rev2_actr">
            <hardwareInterface>hardware_interface/EffortJointInterface</hardwareInterface>
            <mechanicalReduction>1</mechanicalReduction>
        </actuator>
    </transmission>
    <transmission name="d_rev3_tran">
        <type>transmission_interface/SimpleTransmission</type>
        <joint name="d_rev3">
            <hardwareInterface>hardware_interface/EffortJointInterface</hardwareInterface>
        </joint>
        <actuator name="d_rev3_actr">
            <hardwareInterface>hardware_interface/EffortJointInterface</hardwareInterface>
            <mechanicalReduction>1</mechanicalReduction>
        </actuator>
    </transmission>
    <gazebo>
        <plugin filename="libgazebo_ros_control.so" name="control" />
        <plugin name="gazebo_ros_control">
            <robotNamespace>/</robotNamespace>
        </plugin>
    </gazebo>
    <gazebo reference="base_link">
        <material>Gazebo/Silver</material>
        <mu1>0.2</mu1>
        <mu2>0.2</mu2>
        <selfCollide>true</selfCollide>
        <gravity>true</gravity>
    </gazebo>
    <gazebo reference="part1_1">
        <material>Gazebo/Silver</material>
        <mu1>0.2</mu1>
        <mu2>0.2</mu2>
        <selfCollide>true</selfCollide>
    </gazebo>
    <gazebo reference="part2_1">
        <material>Gazebo/Silver</material>
        <mu1>0.2</mu1>
        <mu2>0.2</mu2>
        <selfCollide>true</selfCollide>
    </gazebo>
    <gazebo reference="part3_1">
        <material>Gazebo/Silver</material>
        <mu1>0.2</mu1>
        <mu2>0.2</mu2>
        <selfCollide>true</selfCollide>
    </gazebo>
    <gazebo reference="d_part1_1">
        <material>Gazebo/Silver</material>
        <mu1>0.2</mu1>
        <mu2>0.2</mu2>
        <selfCollide>true</selfCollide>
    </gazebo>
    <gazebo reference="d_part2_1">
        <material>Gazebo/Silver</material>
        <mu1>0.2</mu1>
        <mu2>0.2</mu2>
        <selfCollide>true</selfCollide>
    </gazebo>
    <gazebo reference="d_part3_1">
        <material>Gazebo/Silver</material>
        <mu1>0.2</mu1>
        <mu2>0.2</mu2>
        <selfCollide>true</selfCollide>
    </gazebo>
    <link name="dummy" />
    <link name="base_link">
        <inertial>
            <origin rpy="0 0 0" xyz="-7.237528875152536e-18 -1.447505775030507e-17 0.005" />
            <mass value="0.6165375582669969" />
            <inertia ixx="0.00039" ixy="-0.0" ixz="0.0" iyy="0.00039" iyz="-0.0" izz="0.000771" />
        </inertial>
        <visual>
            <origin rpy="0 0 0" xyz="0 0 0" />
            <geometry>
                <mesh filename="package://moveit_sample_description/meshes/base_link.stl" scale="0.001 0.001 0.001" />
            </geometry>
            <material name="_" />
        </visual>
        <collision>
            <origin rpy="0 0 0" xyz="0 0 0" />
            <geometry>
                <mesh filename="package://moveit_sample_description/meshes/base_link.stl" scale="0.001 0.001 0.001" />
            </geometry>
        </collision>
    </link>
    <link name="part1_1">
        <inertial>
            <origin rpy="0 0 0" xyz="-0.0017277137374306876 6.723447632535409e-13 0.04595059880172599" />
            <mass value="0.09652666146617676" />
            <inertia ixx="0.000103" ixy="-0.0" ixz="4e-06" iyy="0.000102" iyz="-0.0" izz="2e-06" />
        </inertial>
        <visual>
            <origin rpy="0 0 0" xyz="-0.0 -0.0 -0.01" />
            <geometry>
                <mesh filename="package://moveit_sample_description/meshes/part1_1.stl" scale="0.001 0.001 0.001" />
            </geometry>
            <material name="_" />
        </visual>
        <collision>
            <origin rpy="0 0 0" xyz="-0.0 -0.0 -0.01" />
            <geometry>
                <mesh filename="package://moveit_sample_description/meshes/part1_1.stl" scale="0.001 0.001 0.001" />
            </geometry>
        </collision>
    </link>
    <link name="part2_1">
        <inertial>
            <origin rpy="0 0 0" xyz="0.0031621405528323497 0.050000000055879366 -5.586570095417187e-11" />
            <mass value="0.07650347985448655" />
            <inertia ixx="8.1e-05" ixy="-0.0" ixz="-0.0" iyy="1e-06" iyz="-0.0" izz="8e-05" />
        </inertial>
        <visual>
            <origin rpy="0 0 0" xyz="-0.0 -0.0 -0.11" />
            <geometry>
                <mesh filename="package://moveit_sample_description/meshes/part2_1.stl" scale="0.001 0.001 0.001" />
            </geometry>
            <material name="_" />
        </visual>
        <collision>
            <origin rpy="0 0 0" xyz="-0.0 -0.0 -0.11" />
            <geometry>
                <mesh filename="package://moveit_sample_description/meshes/part2_1.stl" scale="0.001 0.001 0.001" />
            </geometry>
        </collision>
    </link>
    <link name="part3_1">
        <inertial>
            <origin rpy="0 0 0" xyz="-0.00307725002425259 0.04554389318565036 -5.588342288920245e-11" />
            <mass value="0.0757185188746656" />
            <inertia ixx="7.5e-05" ixy="0.0" ixz="0.0" iyy="1e-06" iyz="-0.0" izz="7.5e-05" />
        </inertial>
        <visual>
            <origin rpy="0 0 0" xyz="0.0 -0.1 -0.11" />
            <geometry>
                <mesh filename="package://moveit_sample_description/meshes/part3_1.stl" scale="0.001 0.001 0.001" />
            </geometry>
            <material name="_" />
        </visual>
        <collision>
            <origin rpy="0 0 0" xyz="0.0 -0.1 -0.11" />
            <geometry>
                <mesh filename="package://moveit_sample_description/meshes/part3_1.stl" scale="0.001 0.001 0.001" />
            </geometry>
        </collision>
    </link>
    <link name="d_part1_1">
        <inertial>
            <origin rpy="0 0 0" xyz="-2.10969707193732e-33 5.587930118622353e-11 -5.5879384452950376e-11" />
            <mass value="0.0005137812985558307" />
            <inertia ixx="0.0" ixy="0.0" ixz="-0.0" iyy="0.0" iyz="0.0" izz="0.0" />
        </inertial>
        <visual>
            <origin rpy="0 0 0" xyz="0.0 -0.2 -0.11" />
            <geometry>
                <mesh filename="package://moveit_sample_description/meshes/d_part1_1.stl" scale="0.001 0.001 0.001" />
            </geometry>
            <material name="_" />
        </visual>
        <collision>
            <origin rpy="0 0 0" xyz="0.0 -0.2 -0.11" />
            <geometry>
                <mesh filename="package://moveit_sample_description/meshes/d_part1_1.stl" scale="0.001 0.001 0.001" />
            </geometry>
        </collision>
    </link>
    <link name="d_part2_1">
        <inertial>
            <origin rpy="0 0 0" xyz="-2.10969707193732e-33 5.587930118622353e-11 -5.5879384452950376e-11" />
            <mass value="0.004110250388446646" />
            <inertia ixx="0.0" ixy="0.0" ixz="-0.0" iyy="0.0" iyz="0.0" izz="0.0" />
        </inertial>
        <visual>
            <origin rpy="0 0 0" xyz="0.0 -0.2 -0.11" />
            <geometry>
                <mesh filename="package://moveit_sample_description/meshes/d_part2_1.stl" scale="0.001 0.001 0.001" />
            </geometry>
            <material name="_" />
        </visual>
        <collision>
            <origin rpy="0 0 0" xyz="0.0 -0.2 -0.11" />
            <geometry>
                <mesh filename="package://moveit_sample_description/meshes/d_part2_1.stl" scale="0.001 0.001 0.001" />
            </geometry>
        </collision>
    </link>
    <link name="d_part3_1">
        <inertial>
            <origin rpy="0 0 0" xyz="-2.10969707193732e-33 5.587930118622353e-11 -5.5879384452950376e-11" />
            <mass value="0.004110250388446646" />
            <inertia ixx="0.0" ixy="0.0" ixz="-0.0" iyy="0.0" iyz="0.0" izz="0.0" />
        </inertial>
        <visual>
            <origin rpy="0 0 0" xyz="0.0 -0.2 -0.11" />
            <geometry>
                <mesh filename="package://moveit_sample_description/meshes/d_part3_1.stl" scale="0.001 0.001 0.001" />
            </geometry>
            <material name="_" />
        </visual>
        <collision>
            <origin rpy="0 0 0" xyz="0.0 -0.2 -0.11" />
            <geometry>
                <mesh filename="package://moveit_sample_description/meshes/d_part3_1.stl" scale="0.001 0.001 0.001" />
            </geometry>
        </collision>
    </link>
    <joint name="dummy_joint" type="fixed">
        <parent link="dummy" />
        <child link="base_link" />
    </joint>
    <joint name="rev1" type="continuous">
        <origin rpy="0 0 0" xyz="0.0 0.0 0.01" />
        <parent link="base_link" />
        <child link="part1_1" />
        <axis xyz="0.0 0.0 1.0" />
    </joint>
    <joint name="rev2" type="continuous">
        <origin rpy="0 0 0" xyz="0.0 0.0 0.1" />
        <parent link="part1_1" />
        <child link="part2_1" />
        <axis xyz="-1.0 0.0 0.0" />
    </joint>
    <joint name="rev3" type="continuous">
        <origin rpy="0 0 0" xyz="-0.0 0.1 0.0" />
        <parent link="part2_1" />
        <child link="part3_1" />
        <axis xyz="1.0 -0.0 0.0" />
    </joint>
    <joint name="d_rev1" type="continuous">
        <origin rpy="0 0 0" xyz="0.0 0.1 0.0" />
        <parent link="part3_1" />
        <child link="d_part1_1" />
        <axis xyz="1.0 0.0 0.0" />
    </joint>
    <joint name="d_rev2" type="continuous">
        <origin rpy="0 0 0" xyz="0.0 0.0 0.0" />
        <parent link="d_part1_1" />
        <child link="d_part2_1" />
        <axis xyz="-0.0 1.0 -0.0" />
    </joint>
    <joint name="d_rev3" type="continuous">
        <origin rpy="0 0 0" xyz="0.0 0.0 0.0" />
        <parent link="d_part2_1" />
        <child link="d_part3_1" />
        <axis xyz="-0.0 0.0 1.0" />
    </joint>
</robot>

